2018-09-27 00:20:28,538 INFO: Microblog startup [in /Users/e83/Documents/GitHub/LearningProjects/FlaskMegaTutorial/ Chapter7/microblog/app/__init__.py:53]
2018-09-27 00:20:59,036 INFO: Microblog startup [in /Users/e83/Documents/GitHub/LearningProjects/FlaskMegaTutorial/ Chapter7/microblog/app/__init__.py:53]
2018-09-29 19:21:33,596 INFO: Microblog startup [in /Users/e83/Documents/GitHub/LearningProjects/Flask_Mega_Tutorial/ Chapter8/microblog/app/__init__.py:55]
2018-09-29 19:21:47,317 INFO: Microblog startup [in /Users/e83/Documents/GitHub/LearningProjects/Flask_Mega_Tutorial/ Chapter8/microblog/app/__init__.py:55]
2018-09-29 19:44:32,050 INFO: Microblog startup [in /Users/e83/Documents/GitHub/LearningProjects/Flask_Mega_Tutorial/ Chapter8/microblog/app/__init__.py:55]
2018-09-29 19:53:54,772 INFO: Microblog startup [in /Users/e83/Documents/GitHub/LearningProjects/Flask_Mega_Tutorial/ Chapter8/microblog/app/__init__.py:55]
2018-09-29 19:54:33,323 INFO: Microblog startup [in /Users/e83/Documents/GitHub/LearningProjects/Flask_Mega_Tutorial/ Chapter8/microblog/app/__init__.py:55]
2018-09-30 12:08:07,905 INFO: Microblog startup [in /Users/e83/Documents/GitHub/LearningProjects/Flask_Mega_Tutorial/ Chapter8/microblog/app/__init__.py:55]
2018-09-30 12:08:47,381 INFO: Microblog startup [in /Users/e83/Documents/GitHub/LearningProjects/Flask_Mega_Tutorial/ Chapter8/microblog/app/__init__.py:55]
2018-09-30 12:09:19,457 INFO: Microblog startup [in /Users/e83/Documents/GitHub/LearningProjects/Flask_Mega_Tutorial/ Chapter8/microblog/app/__init__.py:55]
2018-09-30 12:10:50,663 INFO: Microblog startup [in /Users/e83/Documents/GitHub/LearningProjects/Flask_Mega_Tutorial/ Chapter8/microblog/app/__init__.py:55]
2018-09-30 12:11:03,678 INFO: Microblog startup [in /Users/e83/Documents/GitHub/LearningProjects/Flask_Mega_Tutorial/ Chapter8/microblog/app/__init__.py:55]
2018-09-30 12:29:34,774 INFO: Microblog startup [in /Users/e83/Documents/GitHub/LearningProjects/Flask_Mega_Tutorial/ Chapter8/microblog/app/__init__.py:55]
2018-09-30 12:29:39,958 INFO: Microblog startup [in /Users/e83/Documents/GitHub/LearningProjects/Flask_Mega_Tutorial/ Chapter8/microblog/app/__init__.py:55]
2018-09-30 21:24:14,225 INFO: Microblog startup [in /Users/e83/Documents/GitHub/LearningProjects/Flask_Mega_Tutorial/ Chapter9/microblog/app/__init__.py:55]
2018-10-01 08:55:38,482 INFO: Microblog startup [in /Users/e83/Documents/GitHub/LearningProjects/Flask_Mega_Tutorial/ Chapter9/microblog/app/__init__.py:55]
2018-10-01 08:55:59,898 ERROR: Exception on / [GET] [in /Users/e83/Documents/Code/anaconda3/lib/python3.5/site-packages/flask/app.py:1587]
Traceback (most recent call last):
  File "/Users/e83/Documents/Code/anaconda3/lib/python3.5/site-packages/flask/app.py", line 1988, in wsgi_app
    response = self.full_dispatch_request()
  File "/Users/e83/Documents/Code/anaconda3/lib/python3.5/site-packages/flask/app.py", line 1641, in full_dispatch_request
    rv = self.handle_user_exception(e)
  File "/Users/e83/Documents/Code/anaconda3/lib/python3.5/site-packages/flask/app.py", line 1544, in handle_user_exception
    reraise(exc_type, exc_value, tb)
  File "/Users/e83/Documents/Code/anaconda3/lib/python3.5/site-packages/flask/_compat.py", line 33, in reraise
    raise value
  File "/Users/e83/Documents/Code/anaconda3/lib/python3.5/site-packages/flask/app.py", line 1639, in full_dispatch_request
    rv = self.dispatch_request()
  File "/Users/e83/Documents/Code/anaconda3/lib/python3.5/site-packages/flask/app.py", line 1625, in dispatch_request
    return self.view_functions[rule.endpoint](**req.view_args)
  File "/Users/e83/Documents/Code/anaconda3/lib/python3.5/site-packages/flask_login/utils.py", line 261, in decorated_view
    return func(*args, **kwargs)
  File "/Users/e83/Documents/GitHub/LearningProjects/Flask_Mega_Tutorial/ Chapter9/microblog/app/routes.py", line 22, in index
    posts = current_user.followed_posts.all()
AttributeError: 'function' object has no attribute 'all'
2018-10-01 08:57:56,134 INFO: Microblog startup [in /Users/e83/Documents/GitHub/LearningProjects/Flask_Mega_Tutorial/ Chapter9/microblog/app/__init__.py:55]
2018-10-01 09:01:57,493 INFO: Microblog startup [in /Users/e83/Documents/GitHub/LearningProjects/Flask_Mega_Tutorial/ Chapter9/microblog/app/__init__.py:55]
2018-10-01 09:02:55,351 INFO: Microblog startup [in /Users/e83/Documents/GitHub/LearningProjects/Flask_Mega_Tutorial/ Chapter9/microblog/app/__init__.py:55]
2018-10-01 09:27:06,294 INFO: Microblog startup [in /Users/e83/Documents/GitHub/LearningProjects/Flask_Mega_Tutorial/ Chapter9/microblog/app/__init__.py:55]
2018-10-01 09:27:19,755 ERROR: Exception on / [GET] [in /Users/e83/Documents/Code/anaconda3/lib/python3.5/site-packages/flask/app.py:1587]
Traceback (most recent call last):
  File "/Users/e83/Documents/Code/anaconda3/lib/python3.5/site-packages/flask/app.py", line 1988, in wsgi_app
    response = self.full_dispatch_request()
  File "/Users/e83/Documents/Code/anaconda3/lib/python3.5/site-packages/flask/app.py", line 1641, in full_dispatch_request
    rv = self.handle_user_exception(e)
  File "/Users/e83/Documents/Code/anaconda3/lib/python3.5/site-packages/flask/app.py", line 1544, in handle_user_exception
    reraise(exc_type, exc_value, tb)
  File "/Users/e83/Documents/Code/anaconda3/lib/python3.5/site-packages/flask/_compat.py", line 33, in reraise
    raise value
  File "/Users/e83/Documents/Code/anaconda3/lib/python3.5/site-packages/flask/app.py", line 1639, in full_dispatch_request
    rv = self.dispatch_request()
  File "/Users/e83/Documents/Code/anaconda3/lib/python3.5/site-packages/flask/app.py", line 1625, in dispatch_request
    return self.view_functions[rule.endpoint](**req.view_args)
  File "/Users/e83/Documents/Code/anaconda3/lib/python3.5/site-packages/flask_login/utils.py", line 261, in decorated_view
    return func(*args, **kwargs)
  File "/Users/e83/Documents/GitHub/LearningProjects/Flask_Mega_Tutorial/ Chapter9/microblog/app/routes.py", line 24, in index
    page, app.config(['POSTS_PER_PAGE']), False)
NameError: name 'app' is not defined
2018-10-01 09:27:44,010 INFO: Microblog startup [in /Users/e83/Documents/GitHub/LearningProjects/Flask_Mega_Tutorial/ Chapter9/microblog/app/__init__.py:55]
2018-10-01 09:27:47,799 ERROR: Exception on /index [GET] [in /Users/e83/Documents/Code/anaconda3/lib/python3.5/site-packages/flask/app.py:1587]
Traceback (most recent call last):
  File "/Users/e83/Documents/Code/anaconda3/lib/python3.5/site-packages/flask/app.py", line 1988, in wsgi_app
    response = self.full_dispatch_request()
  File "/Users/e83/Documents/Code/anaconda3/lib/python3.5/site-packages/flask/app.py", line 1641, in full_dispatch_request
    rv = self.handle_user_exception(e)
  File "/Users/e83/Documents/Code/anaconda3/lib/python3.5/site-packages/flask/app.py", line 1544, in handle_user_exception
    reraise(exc_type, exc_value, tb)
  File "/Users/e83/Documents/Code/anaconda3/lib/python3.5/site-packages/flask/_compat.py", line 33, in reraise
    raise value
  File "/Users/e83/Documents/Code/anaconda3/lib/python3.5/site-packages/flask/app.py", line 1639, in full_dispatch_request
    rv = self.dispatch_request()
  File "/Users/e83/Documents/Code/anaconda3/lib/python3.5/site-packages/flask/app.py", line 1625, in dispatch_request
    return self.view_functions[rule.endpoint](**req.view_args)
  File "/Users/e83/Documents/Code/anaconda3/lib/python3.5/site-packages/flask_login/utils.py", line 261, in decorated_view
    return func(*args, **kwargs)
  File "/Users/e83/Documents/GitHub/LearningProjects/Flask_Mega_Tutorial/ Chapter9/microblog/app/routes.py", line 24, in index
    page, instance_of_Flask.config(['POSTS_PER_PAGE']), False)
TypeError: 'Config' object is not callable
2018-10-01 09:27:49,567 ERROR: Exception on /index [GET] [in /Users/e83/Documents/Code/anaconda3/lib/python3.5/site-packages/flask/app.py:1587]
Traceback (most recent call last):
  File "/Users/e83/Documents/Code/anaconda3/lib/python3.5/site-packages/flask/app.py", line 1988, in wsgi_app
    response = self.full_dispatch_request()
  File "/Users/e83/Documents/Code/anaconda3/lib/python3.5/site-packages/flask/app.py", line 1641, in full_dispatch_request
    rv = self.handle_user_exception(e)
  File "/Users/e83/Documents/Code/anaconda3/lib/python3.5/site-packages/flask/app.py", line 1544, in handle_user_exception
    reraise(exc_type, exc_value, tb)
  File "/Users/e83/Documents/Code/anaconda3/lib/python3.5/site-packages/flask/_compat.py", line 33, in reraise
    raise value
  File "/Users/e83/Documents/Code/anaconda3/lib/python3.5/site-packages/flask/app.py", line 1639, in full_dispatch_request
    rv = self.dispatch_request()
  File "/Users/e83/Documents/Code/anaconda3/lib/python3.5/site-packages/flask/app.py", line 1625, in dispatch_request
    return self.view_functions[rule.endpoint](**req.view_args)
  File "/Users/e83/Documents/Code/anaconda3/lib/python3.5/site-packages/flask_login/utils.py", line 261, in decorated_view
    return func(*args, **kwargs)
  File "/Users/e83/Documents/GitHub/LearningProjects/Flask_Mega_Tutorial/ Chapter9/microblog/app/routes.py", line 24, in index
    page, instance_of_Flask.config(['POSTS_PER_PAGE']), False)
TypeError: 'Config' object is not callable
