2018-10-12 13:51:56,276 ERROR: Exception on / [POST] [in /Library/Frameworks/Python.framework/Versions/3.7/lib/python3.7/site-packages/flask/app.py:1761]
Traceback (most recent call last):
  File "/Library/Frameworks/Python.framework/Versions/3.7/lib/python3.7/site-packages/flask/app.py", line 2292, in wsgi_app
    response = self.full_dispatch_request()
  File "/Library/Frameworks/Python.framework/Versions/3.7/lib/python3.7/site-packages/flask/app.py", line 1815, in full_dispatch_request
    rv = self.handle_user_exception(e)
  File "/Library/Frameworks/Python.framework/Versions/3.7/lib/python3.7/site-packages/flask/app.py", line 1718, in handle_user_exception
    reraise(exc_type, exc_value, tb)
  File "/Library/Frameworks/Python.framework/Versions/3.7/lib/python3.7/site-packages/flask/_compat.py", line 35, in reraise
    raise value
  File "/Library/Frameworks/Python.framework/Versions/3.7/lib/python3.7/site-packages/flask/app.py", line 1813, in full_dispatch_request
    rv = self.dispatch_request()
  File "/Library/Frameworks/Python.framework/Versions/3.7/lib/python3.7/site-packages/flask/app.py", line 1799, in dispatch_request
    return self.view_functions[rule.endpoint](**req.view_args)
  File "/Library/Frameworks/Python.framework/Versions/3.7/lib/python3.7/site-packages/flask_login/utils.py", line 261, in decorated_view
    return func(*args, **kwargs)
  File "/Users/evh111/Desktop/programz/petblog/app/routes.py", line 28, in index
    db.session.add(post)
  File "/Library/Frameworks/Python.framework/Versions/3.7/lib/python3.7/site-packages/sqlalchemy/orm/scoping.py", line 153, in do
    return getattr(self.registry(), name)(*args, **kwargs)
  File "/Library/Frameworks/Python.framework/Versions/3.7/lib/python3.7/site-packages/sqlalchemy/orm/session.py", line 1776, in add
    self._save_or_update_state(state)
  File "/Library/Frameworks/Python.framework/Versions/3.7/lib/python3.7/site-packages/sqlalchemy/orm/session.py", line 1789, in _save_or_update_state
    self._save_or_update_impl(state)
  File "/Library/Frameworks/Python.framework/Versions/3.7/lib/python3.7/site-packages/sqlalchemy/orm/session.py", line 2104, in _save_or_update_impl
    self._save_impl(state)
  File "/Library/Frameworks/Python.framework/Versions/3.7/lib/python3.7/site-packages/sqlalchemy/orm/session.py", line 2056, in _save_impl
    to_attach = self._before_attach(state, obj)
  File "/Library/Frameworks/Python.framework/Versions/3.7/lib/python3.7/site-packages/sqlalchemy/orm/session.py", line 2179, in _before_attach
    state.session_id, self.hash_key))
sqlalchemy.exc.InvalidRequestError: Object '<Post at 0x110c83cc0>' is already attached to session '3' (this is '4')
2018-10-12 13:56:30,953 INFO: PetBlog startup [in /Users/evh111/Desktop/programz/petblog/app/__init__.py:47]
2018-10-12 13:56:39,229 ERROR: Exception on / [POST] [in /Library/Frameworks/Python.framework/Versions/3.7/lib/python3.7/site-packages/flask/app.py:1761]
Traceback (most recent call last):
  File "/Library/Frameworks/Python.framework/Versions/3.7/lib/python3.7/site-packages/flask/app.py", line 2292, in wsgi_app
    response = self.full_dispatch_request()
  File "/Library/Frameworks/Python.framework/Versions/3.7/lib/python3.7/site-packages/flask/app.py", line 1815, in full_dispatch_request
    rv = self.handle_user_exception(e)
  File "/Library/Frameworks/Python.framework/Versions/3.7/lib/python3.7/site-packages/flask/app.py", line 1718, in handle_user_exception
    reraise(exc_type, exc_value, tb)
  File "/Library/Frameworks/Python.framework/Versions/3.7/lib/python3.7/site-packages/flask/_compat.py", line 35, in reraise
    raise value
  File "/Library/Frameworks/Python.framework/Versions/3.7/lib/python3.7/site-packages/flask/app.py", line 1813, in full_dispatch_request
    rv = self.dispatch_request()
  File "/Library/Frameworks/Python.framework/Versions/3.7/lib/python3.7/site-packages/flask/app.py", line 1799, in dispatch_request
    return self.view_functions[rule.endpoint](**req.view_args)
  File "/Library/Frameworks/Python.framework/Versions/3.7/lib/python3.7/site-packages/flask_login/utils.py", line 261, in decorated_view
    return func(*args, **kwargs)
  File "/Users/evh111/Desktop/programz/petblog/app/routes.py", line 28, in index
    db.session.expunge()
  File "/Library/Frameworks/Python.framework/Versions/3.7/lib/python3.7/site-packages/sqlalchemy/orm/scoping.py", line 153, in do
    return getattr(self.registry(), name)(*args, **kwargs)
TypeError: expunge() missing 1 required positional argument: 'instance'
2018-10-12 13:57:01,798 INFO: PetBlog startup [in /Users/evh111/Desktop/programz/petblog/app/__init__.py:47]
2018-10-12 13:57:09,018 ERROR: Exception on / [POST] [in /Library/Frameworks/Python.framework/Versions/3.7/lib/python3.7/site-packages/flask/app.py:1761]
Traceback (most recent call last):
  File "/Library/Frameworks/Python.framework/Versions/3.7/lib/python3.7/site-packages/flask/app.py", line 2292, in wsgi_app
    response = self.full_dispatch_request()
  File "/Library/Frameworks/Python.framework/Versions/3.7/lib/python3.7/site-packages/flask/app.py", line 1815, in full_dispatch_request
    rv = self.handle_user_exception(e)
  File "/Library/Frameworks/Python.framework/Versions/3.7/lib/python3.7/site-packages/flask/app.py", line 1718, in handle_user_exception
    reraise(exc_type, exc_value, tb)
  File "/Library/Frameworks/Python.framework/Versions/3.7/lib/python3.7/site-packages/flask/_compat.py", line 35, in reraise
    raise value
  File "/Library/Frameworks/Python.framework/Versions/3.7/lib/python3.7/site-packages/flask/app.py", line 1813, in full_dispatch_request
    rv = self.dispatch_request()
  File "/Library/Frameworks/Python.framework/Versions/3.7/lib/python3.7/site-packages/flask/app.py", line 1799, in dispatch_request
    return self.view_functions[rule.endpoint](**req.view_args)
  File "/Library/Frameworks/Python.framework/Versions/3.7/lib/python3.7/site-packages/flask_login/utils.py", line 261, in decorated_view
    return func(*args, **kwargs)
  File "/Users/evh111/Desktop/programz/petblog/app/routes.py", line 28, in index
    db.session.expunge(post)
  File "/Library/Frameworks/Python.framework/Versions/3.7/lib/python3.7/site-packages/sqlalchemy/orm/scoping.py", line 153, in do
    return getattr(self.registry(), name)(*args, **kwargs)
  File "/Library/Frameworks/Python.framework/Versions/3.7/lib/python3.7/site-packages/sqlalchemy/orm/session.py", line 1650, in expunge
    state_str(state))
sqlalchemy.exc.InvalidRequestError: Instance <Post at 0x108c9bda0> is not present in this Session
2018-10-12 13:59:33,667 INFO: PetBlog startup [in /Users/evh111/Desktop/programz/petblog/app/__init__.py:47]
2018-10-12 13:59:38,580 ERROR: Exception on / [POST] [in /Library/Frameworks/Python.framework/Versions/3.7/lib/python3.7/site-packages/flask/app.py:1761]
Traceback (most recent call last):
  File "/Library/Frameworks/Python.framework/Versions/3.7/lib/python3.7/site-packages/flask/app.py", line 2292, in wsgi_app
    response = self.full_dispatch_request()
  File "/Library/Frameworks/Python.framework/Versions/3.7/lib/python3.7/site-packages/flask/app.py", line 1815, in full_dispatch_request
    rv = self.handle_user_exception(e)
  File "/Library/Frameworks/Python.framework/Versions/3.7/lib/python3.7/site-packages/flask/app.py", line 1718, in handle_user_exception
    reraise(exc_type, exc_value, tb)
  File "/Library/Frameworks/Python.framework/Versions/3.7/lib/python3.7/site-packages/flask/_compat.py", line 35, in reraise
    raise value
  File "/Library/Frameworks/Python.framework/Versions/3.7/lib/python3.7/site-packages/flask/app.py", line 1813, in full_dispatch_request
    rv = self.dispatch_request()
  File "/Library/Frameworks/Python.framework/Versions/3.7/lib/python3.7/site-packages/flask/app.py", line 1799, in dispatch_request
    return self.view_functions[rule.endpoint](**req.view_args)
  File "/Library/Frameworks/Python.framework/Versions/3.7/lib/python3.7/site-packages/flask_login/utils.py", line 261, in decorated_view
    return func(*args, **kwargs)
  File "/Users/evh111/Desktop/programz/petblog/app/routes.py", line 28, in index
    db.session.add(post)
  File "/Library/Frameworks/Python.framework/Versions/3.7/lib/python3.7/site-packages/sqlalchemy/orm/scoping.py", line 153, in do
    return getattr(self.registry(), name)(*args, **kwargs)
  File "/Library/Frameworks/Python.framework/Versions/3.7/lib/python3.7/site-packages/sqlalchemy/orm/session.py", line 1776, in add
    self._save_or_update_state(state)
  File "/Library/Frameworks/Python.framework/Versions/3.7/lib/python3.7/site-packages/sqlalchemy/orm/session.py", line 1789, in _save_or_update_state
    self._save_or_update_impl(state)
  File "/Library/Frameworks/Python.framework/Versions/3.7/lib/python3.7/site-packages/sqlalchemy/orm/session.py", line 2104, in _save_or_update_impl
    self._save_impl(state)
  File "/Library/Frameworks/Python.framework/Versions/3.7/lib/python3.7/site-packages/sqlalchemy/orm/session.py", line 2056, in _save_impl
    to_attach = self._before_attach(state, obj)
  File "/Library/Frameworks/Python.framework/Versions/3.7/lib/python3.7/site-packages/sqlalchemy/orm/session.py", line 2179, in _before_attach
    state.session_id, self.hash_key))
sqlalchemy.exc.InvalidRequestError: Object '<Post at 0x10ea0eac8>' is already attached to session '3' (this is '4')
2018-10-12 14:03:44,503 INFO: PetBlog startup [in /Users/evh111/Desktop/programz/petblog/app/__init__.py:47]
